[2024-03-17T12:13:14.991+0000] {taskinstance.py:1979} INFO - Dependencies all met for dep_context=non-requeueable deps ti=<TaskInstance: movie_night_xcom.save_data manual__2024-03-17T12:13:07.629995+00:00 [queued]>
[2024-03-17T12:13:15.008+0000] {taskinstance.py:1979} INFO - Dependencies all met for dep_context=requeueable deps ti=<TaskInstance: movie_night_xcom.save_data manual__2024-03-17T12:13:07.629995+00:00 [queued]>
[2024-03-17T12:13:15.009+0000] {taskinstance.py:2193} INFO - Starting attempt 1 of 1
[2024-03-17T12:13:15.034+0000] {taskinstance.py:2214} INFO - Executing <Task(PythonOperator): save_data> on 2024-03-17 12:13:07.629995+00:00
[2024-03-17T12:13:15.042+0000] {standard_task_runner.py:60} INFO - Started process 979 to run task
[2024-03-17T12:13:15.047+0000] {standard_task_runner.py:87} INFO - Running: ['***', 'tasks', 'run', 'movie_night_xcom', 'save_data', 'manual__2024-03-17T12:13:07.629995+00:00', '--job-id', '17', '--raw', '--subdir', 'DAGS_FOLDER/simple_insert_ti_xcom.py', '--cfg-path', '/tmp/tmp6booz2l0']
[2024-03-17T12:13:15.050+0000] {standard_task_runner.py:88} INFO - Job 17: Subtask save_data
[2024-03-17T12:13:15.137+0000] {task_command.py:423} INFO - Running <TaskInstance: movie_night_xcom.save_data manual__2024-03-17T12:13:07.629995+00:00 [running]> on host cd3e1c58e82e
[2024-03-17T12:13:15.276+0000] {taskinstance.py:2510} INFO - Exporting env vars: AIRFLOW_CTX_DAG_OWNER='***' AIRFLOW_CTX_DAG_ID='movie_night_xcom' AIRFLOW_CTX_TASK_ID='save_data' AIRFLOW_CTX_EXECUTION_DATE='2024-03-17T12:13:07.629995+00:00' AIRFLOW_CTX_TRY_NUMBER='1' AIRFLOW_CTX_DAG_RUN_ID='manual__2024-03-17T12:13:07.629995+00:00'
[2024-03-17T12:13:15.279+0000] {taskinstance.py:2728} ERROR - Task failed with exception
Traceback (most recent call last):
  File "/home/airflow/.local/lib/python3.8/site-packages/airflow/models/taskinstance.py", line 444, in _execute_task
    result = _execute_callable(context=context, **execute_callable_kwargs)
  File "/home/airflow/.local/lib/python3.8/site-packages/airflow/models/taskinstance.py", line 414, in _execute_callable
    return execute_callable(context=context, **execute_callable_kwargs)
  File "/home/airflow/.local/lib/python3.8/site-packages/airflow/operators/python.py", line 200, in execute
    return_value = self.execute_callable()
  File "/home/airflow/.local/lib/python3.8/site-packages/airflow/operators/python.py", line 217, in execute_callable
    return self.python_callable(*self.op_args, **self.op_kwargs)
  File "/opt/airflow/dags/simple_insert_ti_xcom.py", line 89, in save_data
    transformed_data = ti.xcom_pull(key='return_value', task_id='transform_data')
  File "/home/airflow/.local/lib/python3.8/site-packages/airflow/utils/session.py", line 79, in wrapper
    return func(*args, session=session, **kwargs)
TypeError: xcom_pull() got an unexpected keyword argument 'task_id'
[2024-03-17T12:13:15.303+0000] {taskinstance.py:1149} INFO - Marking task as FAILED. dag_id=movie_night_xcom, task_id=save_data, execution_date=20240317T121307, start_date=20240317T121314, end_date=20240317T121315
[2024-03-17T12:13:15.329+0000] {standard_task_runner.py:107} ERROR - Failed to execute job 17 for task save_data (xcom_pull() got an unexpected keyword argument 'task_id'; 979)
[2024-03-17T12:13:15.344+0000] {local_task_job_runner.py:234} INFO - Task exited with return code 1
[2024-03-17T12:13:15.378+0000] {taskinstance.py:3309} INFO - 0 downstream tasks scheduled from follow-on schedule check
