[2024-05-05T11:00:48.820+0000] {taskinstance.py:1979} INFO - Dependencies all met for dep_context=non-requeueable deps ti=<TaskInstance: currency_parsing.run_dbt scheduled__2024-05-02T00:00:00+00:00 [queued]>
[2024-05-05T11:00:48.847+0000] {taskinstance.py:1979} INFO - Dependencies all met for dep_context=requeueable deps ti=<TaskInstance: currency_parsing.run_dbt scheduled__2024-05-02T00:00:00+00:00 [queued]>
[2024-05-05T11:00:48.848+0000] {taskinstance.py:2193} INFO - Starting attempt 2 of 2
[2024-05-05T11:00:48.875+0000] {taskinstance.py:2214} INFO - Executing <Task(PythonOperator): run_dbt> on 2024-05-02 00:00:00+00:00
[2024-05-05T11:00:48.882+0000] {standard_task_runner.py:60} INFO - Started process 897 to run task
[2024-05-05T11:00:48.888+0000] {standard_task_runner.py:87} INFO - Running: ['***', 'tasks', 'run', 'currency_parsing', 'run_dbt', 'scheduled__2024-05-02T00:00:00+00:00', '--job-id', '2733', '--raw', '--subdir', 'DAGS_FOLDER/currency_dag/currency_parsing.py', '--cfg-path', '/tmp/tmpuc463hd8']
[2024-05-05T11:00:48.892+0000] {standard_task_runner.py:88} INFO - Job 2733: Subtask run_dbt
[2024-05-05T11:00:49.083+0000] {task_command.py:423} INFO - Running <TaskInstance: currency_parsing.run_dbt scheduled__2024-05-02T00:00:00+00:00 [running]> on host 71addd39200f
[2024-05-05T11:00:49.353+0000] {taskinstance.py:2510} INFO - Exporting env vars: AIRFLOW_CTX_DAG_OWNER='***' AIRFLOW_CTX_DAG_ID='currency_parsing' AIRFLOW_CTX_TASK_ID='run_dbt' AIRFLOW_CTX_EXECUTION_DATE='2024-05-02T00:00:00+00:00' AIRFLOW_CTX_TRY_NUMBER='2' AIRFLOW_CTX_DAG_RUN_ID='scheduled__2024-05-02T00:00:00+00:00'
[2024-05-05T11:00:49.378+0000] {taskinstance.py:2728} ERROR - Task failed with exception
Traceback (most recent call last):
  File "/home/airflow/.local/lib/python3.8/site-packages/airflow/models/taskinstance.py", line 444, in _execute_task
    result = _execute_callable(context=context, **execute_callable_kwargs)
  File "/home/airflow/.local/lib/python3.8/site-packages/airflow/models/taskinstance.py", line 414, in _execute_callable
    return execute_callable(context=context, **execute_callable_kwargs)
  File "/home/airflow/.local/lib/python3.8/site-packages/airflow/operators/python.py", line 200, in execute
    return_value = self.execute_callable()
  File "/home/airflow/.local/lib/python3.8/site-packages/airflow/operators/python.py", line 217, in execute_callable
    return self.python_callable(*self.op_args, **self.op_kwargs)
  File "/opt/airflow/dags/currency_dag/currency_parsing.py", line 108, in run_dbt
    subprocess.run(['dbt', 'run', '--profiles-dir', '/dags/currency_dag/dbt_currency'])
  File "/usr/local/lib/python3.8/subprocess.py", line 493, in run
    with Popen(*popenargs, **kwargs) as process:
  File "/usr/local/lib/python3.8/subprocess.py", line 858, in __init__
    self._execute_child(args, executable, preexec_fn, close_fds,
  File "/usr/local/lib/python3.8/subprocess.py", line 1720, in _execute_child
    raise child_exception_type(errno_num, err_msg, err_filename)
PermissionError: [Errno 13] Permission denied: 'dbt'
[2024-05-05T11:00:49.448+0000] {taskinstance.py:1149} INFO - Marking task as FAILED. dag_id=currency_parsing, task_id=run_dbt, execution_date=20240502T000000, start_date=20240505T110048, end_date=20240505T110049
[2024-05-05T11:00:49.499+0000] {standard_task_runner.py:107} ERROR - Failed to execute job 2733 for task run_dbt ([Errno 13] Permission denied: 'dbt'; 897)
[2024-05-05T11:00:49.555+0000] {local_task_job_runner.py:234} INFO - Task exited with return code 1
[2024-05-05T11:00:49.627+0000] {taskinstance.py:3309} INFO - 0 downstream tasks scheduled from follow-on schedule check
