[2024-04-21T11:04:39.142+0000] {taskinstance.py:1979} INFO - Dependencies all met for dep_context=non-requeueable deps ti=<TaskInstance: currency_parsing.get_data_usd scheduled__2024-04-09T00:00:00+00:00 [queued]>
[2024-04-21T11:04:39.363+0000] {taskinstance.py:1979} INFO - Dependencies all met for dep_context=requeueable deps ti=<TaskInstance: currency_parsing.get_data_usd scheduled__2024-04-09T00:00:00+00:00 [queued]>
[2024-04-21T11:04:39.381+0000] {taskinstance.py:2193} INFO - Starting attempt 1 of 2
[2024-04-21T11:04:39.701+0000] {taskinstance.py:2214} INFO - Executing <Task(PythonOperator): get_data_usd> on 2024-04-09 00:00:00+00:00
[2024-04-21T11:04:39.721+0000] {standard_task_runner.py:60} INFO - Started process 2540 to run task
[2024-04-21T11:04:39.805+0000] {standard_task_runner.py:87} INFO - Running: ['***', 'tasks', 'run', 'currency_parsing', 'get_data_usd', 'scheduled__2024-04-09T00:00:00+00:00', '--job-id', '1988', '--raw', '--subdir', 'DAGS_FOLDER/stage/currency_parsing.py', '--cfg-path', '/tmp/tmpyie4eeyk']
[2024-04-21T11:04:39.959+0000] {standard_task_runner.py:88} INFO - Job 1988: Subtask get_data_usd
[2024-04-21T11:04:41.003+0000] {task_command.py:423} INFO - Running <TaskInstance: currency_parsing.get_data_usd scheduled__2024-04-09T00:00:00+00:00 [running]> on host e671688b1343
[2024-04-21T11:04:41.492+0000] {warnings.py:109} WARNING - /home/***/.local/lib/python3.8/site-packages/***/utils/context.py:207: AirflowContextDeprecationWarning: Accessing 'execution_date' from the template is deprecated and will be removed in a future version. Please use 'data_interval_start' or 'logical_date' instead.
  warnings.warn(_create_deprecation_warning(key, self._deprecation_replacements[key]))

[2024-04-21T11:04:41.793+0000] {taskinstance.py:2510} INFO - Exporting env vars: AIRFLOW_CTX_DAG_OWNER='***' AIRFLOW_CTX_DAG_ID='currency_parsing' AIRFLOW_CTX_TASK_ID='get_data_usd' AIRFLOW_CTX_EXECUTION_DATE='2024-04-09T00:00:00+00:00' AIRFLOW_CTX_TRY_NUMBER='1' AIRFLOW_CTX_DAG_RUN_ID='scheduled__2024-04-09T00:00:00+00:00'
[2024-04-21T11:04:42.940+0000] {python.py:202} INFO - Done. Returned value was: ([['AUD', 1.5142101763, '2024-4-8'], ['BGN', 1.8014403566, '2024-4-8'], ['BRL', 5.0286607976, '2024-4-8'], ['CAD', 1.3569802523, '2024-4-8'], ['CHF', 0.9052201522, '2024-4-8'], ['CNY', 7.2297412849, '2024-4-8'], ['CZK', 23.3079730899, '2024-4-8'], ['DKK', 6.866721135, '2024-4-8'], ['EUR', 0.9206201352, '2024-4-8'], ['GBP', 0.7901301207, '2024-4-8'], ['HKD', 7.8307709067, '2024-4-8'], ['HRK', 6.6888607626, '2024-4-8'], ['HUF', 358.4754176983, '2024-4-8'], ['IDR', 15821.701106101, '2024-4-8'], ['ILS', 3.6933905078, '2024-4-8'], ['INR', 83.2531421087, '2024-4-8'], ['ISK', 138.3902058283, '2024-4-8'], ['JPY', 151.8390570028, '2024-4-8'], ['KRW', 1350.2897670916, '2024-4-8'], ['MXN', 16.3233528212, '2024-4-8'], ['MYR', 4.7508504796, '2024-4-8'], ['NOK', 10.677461706, '2024-4-8'], ['NZD', 1.6572501992, '2024-4-8'], ['PHP', 56.531637934, '2024-4-8'], ['PLN', 3.9206806281, '2024-4-8'], ['RON', 4.5727805899, '2024-4-8'], ['RUB', 92.6020016149, '2024-4-8'], ['SEK', 10.5572013051, '2024-4-8'], ['SGD', 1.3473902442, '2024-4-8'], ['THB', 36.7108456453, '2024-4-8'], ['TRY', 32.1362854518, '2024-4-8'], ['USD', 1, '2024-4-8'], ['ZAR', 18.6319624874, '2024-4-8']], ['title', 'rate', 'date'])
[2024-04-21T11:04:43.357+0000] {taskinstance.py:1149} INFO - Marking task as SUCCESS. dag_id=currency_parsing, task_id=get_data_usd, execution_date=20240409T000000, start_date=20240421T110439, end_date=20240421T110443
[2024-04-21T11:04:43.536+0000] {local_task_job_runner.py:234} INFO - Task exited with return code 0
[2024-04-21T11:04:44.166+0000] {taskinstance.py:3309} INFO - 0 downstream tasks scheduled from follow-on schedule check
[2024-04-27T12:19:36.577+0000] {taskinstance.py:1979} INFO - Dependencies all met for dep_context=non-requeueable deps ti=<TaskInstance: currency_parsing.get_data_usd scheduled__2024-04-09T00:00:00+00:00 [queued]>
[2024-04-27T12:19:36.837+0000] {taskinstance.py:1979} INFO - Dependencies all met for dep_context=requeueable deps ti=<TaskInstance: currency_parsing.get_data_usd scheduled__2024-04-09T00:00:00+00:00 [queued]>
[2024-04-27T12:19:37.591+0000] {taskinstance.py:2193} INFO - Starting attempt 1 of 2
[2024-04-27T12:19:38.865+0000] {taskinstance.py:2214} INFO - Executing <Task(PythonOperator): get_data_usd> on 2024-04-09 00:00:00+00:00
[2024-04-27T12:19:38.931+0000] {standard_task_runner.py:60} INFO - Started process 1929 to run task
[2024-04-27T12:19:39.481+0000] {standard_task_runner.py:87} INFO - Running: ['***', 'tasks', 'run', 'currency_parsing', 'get_data_usd', 'scheduled__2024-04-09T00:00:00+00:00', '--job-id', '2321', '--raw', '--subdir', 'DAGS_FOLDER/stage/currency_parsing.py', '--cfg-path', '/tmp/tmpm8vfjutl']
[2024-04-27T12:19:39.763+0000] {standard_task_runner.py:88} INFO - Job 2321: Subtask get_data_usd
[2024-04-27T12:19:41.509+0000] {task_command.py:423} INFO - Running <TaskInstance: currency_parsing.get_data_usd scheduled__2024-04-09T00:00:00+00:00 [running]> on host 65a8688265d1
[2024-04-27T12:19:42.505+0000] {warnings.py:109} WARNING - /home/***/.local/lib/python3.8/site-packages/***/utils/context.py:207: AirflowContextDeprecationWarning: Accessing 'execution_date' from the template is deprecated and will be removed in a future version. Please use 'data_interval_start' or 'logical_date' instead.
  warnings.warn(_create_deprecation_warning(key, self._deprecation_replacements[key]))

[2024-04-27T12:19:43.812+0000] {taskinstance.py:2510} INFO - Exporting env vars: AIRFLOW_CTX_DAG_OWNER='***' AIRFLOW_CTX_DAG_ID='currency_parsing' AIRFLOW_CTX_TASK_ID='get_data_usd' AIRFLOW_CTX_EXECUTION_DATE='2024-04-09T00:00:00+00:00' AIRFLOW_CTX_TRY_NUMBER='1' AIRFLOW_CTX_DAG_RUN_ID='scheduled__2024-04-09T00:00:00+00:00'
[2024-04-27T12:20:14.192+0000] {taskinstance.py:2728} ERROR - Task failed with exception
Traceback (most recent call last):
  File "/home/airflow/.local/lib/python3.8/site-packages/urllib3/connectionpool.py", line 715, in urlopen
    httplib_response = self._make_request(
  File "/home/airflow/.local/lib/python3.8/site-packages/urllib3/connectionpool.py", line 467, in _make_request
    six.raise_from(e, None)
  File "<string>", line 3, in raise_from
  File "/home/airflow/.local/lib/python3.8/site-packages/urllib3/connectionpool.py", line 462, in _make_request
    httplib_response = conn.getresponse()
  File "/usr/local/lib/python3.8/http/client.py", line 1348, in getresponse
    response.begin()
  File "/usr/local/lib/python3.8/http/client.py", line 316, in begin
    version, status, reason = self._read_status()
  File "/usr/local/lib/python3.8/http/client.py", line 285, in _read_status
    raise RemoteDisconnected("Remote end closed connection without"
http.client.RemoteDisconnected: Remote end closed connection without response

During handling of the above exception, another exception occurred:

Traceback (most recent call last):
  File "/home/airflow/.local/lib/python3.8/site-packages/requests/adapters.py", line 486, in send
    resp = conn.urlopen(
  File "/home/airflow/.local/lib/python3.8/site-packages/urllib3/connectionpool.py", line 799, in urlopen
    retries = retries.increment(
  File "/home/airflow/.local/lib/python3.8/site-packages/urllib3/util/retry.py", line 550, in increment
    raise six.reraise(type(error), error, _stacktrace)
  File "/home/airflow/.local/lib/python3.8/site-packages/urllib3/packages/six.py", line 769, in reraise
    raise value.with_traceback(tb)
  File "/home/airflow/.local/lib/python3.8/site-packages/urllib3/connectionpool.py", line 715, in urlopen
    httplib_response = self._make_request(
  File "/home/airflow/.local/lib/python3.8/site-packages/urllib3/connectionpool.py", line 467, in _make_request
    six.raise_from(e, None)
  File "<string>", line 3, in raise_from
  File "/home/airflow/.local/lib/python3.8/site-packages/urllib3/connectionpool.py", line 462, in _make_request
    httplib_response = conn.getresponse()
  File "/usr/local/lib/python3.8/http/client.py", line 1348, in getresponse
    response.begin()
  File "/usr/local/lib/python3.8/http/client.py", line 316, in begin
    version, status, reason = self._read_status()
  File "/usr/local/lib/python3.8/http/client.py", line 285, in _read_status
    raise RemoteDisconnected("Remote end closed connection without"
urllib3.exceptions.ProtocolError: ('Connection aborted.', RemoteDisconnected('Remote end closed connection without response'))

During handling of the above exception, another exception occurred:

Traceback (most recent call last):
  File "/home/airflow/.local/lib/python3.8/site-packages/airflow/models/taskinstance.py", line 444, in _execute_task
    result = _execute_callable(context=context, **execute_callable_kwargs)
  File "/home/airflow/.local/lib/python3.8/site-packages/airflow/models/taskinstance.py", line 414, in _execute_callable
    return execute_callable(context=context, **execute_callable_kwargs)
  File "/home/airflow/.local/lib/python3.8/site-packages/airflow/operators/python.py", line 200, in execute
    return_value = self.execute_callable()
  File "/home/airflow/.local/lib/python3.8/site-packages/airflow/operators/python.py", line 217, in execute_callable
    return self.python_callable(*self.op_args, **self.op_kwargs)
  File "/opt/airflow/dags/stage/currency_parsing.py", line 22, in get_data_usd
    currencies_list = get_currency_list(execution_date)
  File "/opt/airflow/dags/stage/currency_utils.py", line 21, in get_currency_list
    data = client.historical(f'{year}-{int(month):02d}-{int(day):02d}', base_currency=base_currency)
  File "/home/airflow/.local/lib/python3.8/site-packages/freecurrencyapi/client.py", line 32, in historical
    return self._request('/historical', params={
  File "/home/airflow/.local/lib/python3.8/site-packages/everapi/client.py", line 43, in _request
    response = requests.request(
  File "/home/airflow/.local/lib/python3.8/site-packages/requests/api.py", line 59, in request
    return session.request(method=method, url=url, **kwargs)
  File "/home/airflow/.local/lib/python3.8/site-packages/requests/sessions.py", line 589, in request
    resp = self.send(prep, **send_kwargs)
  File "/home/airflow/.local/lib/python3.8/site-packages/requests/sessions.py", line 703, in send
    r = adapter.send(request, **kwargs)
  File "/home/airflow/.local/lib/python3.8/site-packages/requests/adapters.py", line 501, in send
    raise ConnectionError(err, request=request)
requests.exceptions.ConnectionError: ('Connection aborted.', RemoteDisconnected('Remote end closed connection without response'))
[2024-04-27T12:20:14.456+0000] {taskinstance.py:1149} INFO - Marking task as UP_FOR_RETRY. dag_id=currency_parsing, task_id=get_data_usd, execution_date=20240409T000000, start_date=20240427T121936, end_date=20240427T122014
[2024-04-27T12:20:16.803+0000] {standard_task_runner.py:107} ERROR - Failed to execute job 2321 for task get_data_usd (('Connection aborted.', RemoteDisconnected('Remote end closed connection without response')); 1929)
[2024-04-27T12:20:17.002+0000] {local_task_job_runner.py:234} INFO - Task exited with return code 1
[2024-04-27T12:20:17.254+0000] {warnings.py:109} WARNING - /home/***/.local/lib/python3.8/site-packages/***/models/baseoperator.py:1201: AirflowProviderDeprecationWarning: Call to deprecated class PostgresOperator. (Please use `***.providers.common.sql.operators.sql.SQLExecuteQueryOperator`.Also, you can provide `hook_params={'schema': <database>}`.)
  result = cls.__new__(cls)

[2024-04-27T12:20:17.911+0000] {taskinstance.py:3309} INFO - 0 downstream tasks scheduled from follow-on schedule check
