[2024-04-07T12:59:48.989+0000] {taskinstance.py:1979} INFO - Dependencies all met for dep_context=non-requeueable deps ti=<TaskInstance: kolesa_dag_2.save_data manual__2024-04-07T12:59:37.756831+00:00 [queued]>
[2024-04-07T12:59:49.022+0000] {taskinstance.py:1979} INFO - Dependencies all met for dep_context=requeueable deps ti=<TaskInstance: kolesa_dag_2.save_data manual__2024-04-07T12:59:37.756831+00:00 [queued]>
[2024-04-07T12:59:49.023+0000] {taskinstance.py:2193} INFO - Starting attempt 1 of 1
[2024-04-07T12:59:49.054+0000] {taskinstance.py:2214} INFO - Executing <Task(PythonOperator): save_data> on 2024-04-07 12:59:37.756831+00:00
[2024-04-07T12:59:49.065+0000] {standard_task_runner.py:60} INFO - Started process 73 to run task
[2024-04-07T12:59:49.072+0000] {standard_task_runner.py:87} INFO - Running: ['***', 'tasks', 'run', 'kolesa_dag_2', 'save_data', 'manual__2024-04-07T12:59:37.756831+00:00', '--job-id', '58', '--raw', '--subdir', 'DAGS_FOLDER/kolesa_parsing_2.py', '--cfg-path', '/tmp/tmpi3_4qrm3']
[2024-04-07T12:59:49.076+0000] {standard_task_runner.py:88} INFO - Job 58: Subtask save_data
[2024-04-07T12:59:49.173+0000] {task_command.py:423} INFO - Running <TaskInstance: kolesa_dag_2.save_data manual__2024-04-07T12:59:37.756831+00:00 [running]> on host 5c454e8a8dea
[2024-04-07T12:59:49.678+0000] {taskinstance.py:2510} INFO - Exporting env vars: AIRFLOW_CTX_DAG_OWNER='***' AIRFLOW_CTX_DAG_ID='kolesa_dag_2' AIRFLOW_CTX_TASK_ID='save_data' AIRFLOW_CTX_EXECUTION_DATE='2024-04-07T12:59:37.756831+00:00' AIRFLOW_CTX_TRY_NUMBER='1' AIRFLOW_CTX_DAG_RUN_ID='manual__2024-04-07T12:59:37.756831+00:00'
[2024-04-07T12:59:49.718+0000] {taskinstance.py:2728} ERROR - Task failed with exception
Traceback (most recent call last):
  File "/home/airflow/.local/lib/python3.8/site-packages/airflow/models/taskinstance.py", line 444, in _execute_task
    result = _execute_callable(context=context, **execute_callable_kwargs)
  File "/home/airflow/.local/lib/python3.8/site-packages/airflow/models/taskinstance.py", line 414, in _execute_callable
    return execute_callable(context=context, **execute_callable_kwargs)
  File "/home/airflow/.local/lib/python3.8/site-packages/airflow/operators/python.py", line 200, in execute
    return_value = self.execute_callable()
  File "/home/airflow/.local/lib/python3.8/site-packages/airflow/operators/python.py", line 217, in execute_callable
    return self.python_callable(*self.op_args, **self.op_kwargs)
  File "/opt/airflow/dags/kolesa_parsing_2.py", line 24, in save_data
    rows, columns = transformed_data
TypeError: cannot unpack non-iterable NoneType object
[2024-04-07T12:59:49.763+0000] {taskinstance.py:1149} INFO - Marking task as FAILED. dag_id=kolesa_dag_2, task_id=save_data, execution_date=20240407T125937, start_date=20240407T125948, end_date=20240407T125949
[2024-04-07T12:59:49.789+0000] {standard_task_runner.py:107} ERROR - Failed to execute job 58 for task save_data (cannot unpack non-iterable NoneType object; 73)
[2024-04-07T12:59:49.843+0000] {local_task_job_runner.py:234} INFO - Task exited with return code 1
[2024-04-07T12:59:49.901+0000] {taskinstance.py:3309} INFO - 0 downstream tasks scheduled from follow-on schedule check
